<sdf version='1.7'>
  <world name='default'>
    <light name='sun' type='directional'>
      <cast_shadows>1</cast_shadows>
      <pose>0 0 10 0 -0 0</pose>
      <diffuse>0.8 0.8 0.8 1</diffuse>
      <specular>0.2 0.2 0.2 1</specular>
      <attenuation>
        <range>1000</range>
        <constant>0.9</constant>
        <linear>0.01</linear>
        <quadratic>0.001</quadratic>
      </attenuation>
      <direction>-0.5 0.1 -0.9</direction>
      <spot>
        <inner_angle>0</inner_angle>
        <outer_angle>0</outer_angle>
        <falloff>0</falloff>
      </spot>
    </light>
    <model name='ground_plane'>
      <static>1</static>
      <link name='link'>
        <collision name='collision'>
          <geometry>
            <plane>
              <normal>0 0 1</normal>
              <size>100 100</size>
            </plane>
          </geometry>
          <surface>
            <contact>
              <collide_bitmask>65535</collide_bitmask>
              <ode/>
            </contact>
            <friction>
              <ode>
                <mu>100</mu>
                <mu2>50</mu2>
              </ode>
              <torsional>
                <ode/>
              </torsional>
            </friction>
            <bounce/>
          </surface>
          <max_contacts>10</max_contacts>
        </collision>
        <visual name='visual'>
          <cast_shadows>0</cast_shadows>
          <geometry>
            <plane>
              <normal>0 0 1</normal>
              <size>100 100</size>
            </plane>
          </geometry>
          <material>
            <script>
              <uri>file://media/materials/scripts/gazebo.material</uri>
              <name>Gazebo/Grey</name>
            </script>
          </material>
        </visual>
        <self_collide>0</self_collide>
        <enable_wind>0</enable_wind>
        <kinematic>0</kinematic>
      </link>
    </model>
    <gravity>0 0 -9.8</gravity>
    <magnetic_field>6e-06 2.3e-05 -4.2e-05</magnetic_field>
    <atmosphere type='adiabatic'/>
    <physics type='ode'>
      <max_step_size>0.001</max_step_size>
      <real_time_factor>1</real_time_factor>
      <real_time_update_rate>1000</real_time_update_rate>
    </physics>
    <scene>
      <ambient>0.4 0.4 0.4 1</ambient>
      <background>0.7 0.7 0.7 1</background>
      <shadows>1</shadows>
    </scene>
    <wind/>
    <spherical_coordinates>
      <surface_model>EARTH_WGS84</surface_model>
      <latitude_deg>0</latitude_deg>
      <longitude_deg>0</longitude_deg>
      <elevation>0</elevation>
      <heading_deg>0</heading_deg>
    </spherical_coordinates>
    <model name='iris'>
      <frame name='iris::__model__' attached_to='iris::base_link'>
        <pose relative_to='__model__'>0 0 0 0 -0 0</pose>
      </frame>
      <link name='iris::base_link'>
        <pose relative_to='iris::__model__'>0 0 0 0 -0 0</pose>
        <inertial>
          <pose>0 0 0 0 -0 0</pose>
          <mass>1.5</mass>
          <inertia>
            <ixx>0.029125</ixx>
            <ixy>0</ixy>
            <ixz>0</ixz>
            <iyy>0.029125</iyy>
            <iyz>0</iyz>
            <izz>0.055225</izz>
          </inertia>
        </inertial>
        <collision name='base_link_inertia_collision'>
          <pose>0 0 0 0 -0 0</pose>
          <geometry>
            <box>
              <size>0.47 0.47 0.11</size>
            </box>
          </geometry>
          <surface>
            <contact>
              <ode>
                <min_depth>0.001</min_depth>
                <max_vel>0</max_vel>
              </ode>
            </contact>
            <friction>
              <ode/>
              <torsional>
                <ode/>
              </torsional>
            </friction>
            <bounce/>
          </surface>
          <max_contacts>10</max_contacts>
        </collision>
        <visual name='base_link_inertia_visual'>
          <pose>0 0 0 0 -0 0</pose>
          <geometry>
            <mesh>
              <scale>1 1 1</scale>
              <uri>model://iris/meshes/iris.stl</uri>
            </mesh>
          </geometry>
          <material>
            <script>
              <name>Gazebo/DarkGrey</name>
              <uri>file://media/materials/scripts/gazebo.material</uri>
            </script>
          </material>
        </visual>
        <gravity>1</gravity>
        <velocity_decay/>
        <self_collide>0</self_collide>
        <enable_wind>0</enable_wind>
        <kinematic>0</kinematic>
      </link>
      <link name='iris::/imu_link'>
        <pose relative_to='iris::__model__'>0 0 0.02 0 -0 0</pose>
        <inertial>
          <pose>0 0 0 0 -0 0</pose>
          <mass>0.015</mass>
          <inertia>
            <ixx>1e-05</ixx>
            <ixy>0</ixy>
            <ixz>0</ixz>
            <iyy>1e-05</iyy>
            <iyz>0</iyz>
            <izz>1e-05</izz>
          </inertia>
        </inertial>
        <self_collide>0</self_collide>
        <enable_wind>0</enable_wind>
        <kinematic>0</kinematic>
      </link>
      <joint name='iris::/imu_joint' type='revolute'>
        <child>iris::/imu_link</child>
        <parent>iris::base_link</parent>
        <axis>
          <xyz expressed_in='iris::__model__'>1 0 0</xyz>
          <limit>
            <lower>0</lower>
            <upper>0</upper>
            <effort>0</effort>
            <velocity>0</velocity>
          </limit>
          <dynamics>
            <spring_reference>0</spring_reference>
            <spring_stiffness>0</spring_stiffness>
          </dynamics>
        </axis>
      </joint>
      <link name='iris::rotor_0'>
        <pose relative_to='iris::__model__'>0.13 -0.22 0.023 0 -0 0</pose>
        <inertial>
          <pose>0 0 0 0 -0 0</pose>
          <mass>0.005</mass>
          <inertia>
            <ixx>9.75e-07</ixx>
            <ixy>0</ixy>
            <ixz>0</ixz>
            <iyy>0.000273104</iyy>
            <iyz>0</iyz>
            <izz>0.000274004</izz>
          </inertia>
        </inertial>
        <collision name='rotor_0_collision'>
          <pose>0 0 0 0 -0 0</pose>
          <geometry>
            <cylinder>
              <length>0.005</length>
              <radius>0.128</radius>
            </cylinder>
          </geometry>
          <surface>
            <contact>
              <ode/>
            </contact>
            <friction>
              <ode/>
              <torsional>
                <ode/>
              </torsional>
            </friction>
            <bounce/>
          </surface>
          <max_contacts>10</max_contacts>
        </collision>
        <visual name='rotor_0_visual'>
          <pose>0 0 0 0 -0 0</pose>
          <geometry>
            <mesh>
              <scale>1 1 1</scale>
              <uri>model://iris/meshes/iris_prop_ccw.dae</uri>
            </mesh>
          </geometry>
          <material>
            <script>
              <name>Gazebo/Blue</name>
              <uri>file://media/materials/scripts/gazebo.material</uri>
            </script>
          </material>
        </visual>
        <gravity>1</gravity>
        <velocity_decay/>
        <self_collide>0</self_collide>
        <enable_wind>0</enable_wind>
        <kinematic>0</kinematic>
      </link>
      <joint name='iris::rotor_0_joint' type='revolute'>
        <child>iris::rotor_0</child>
        <parent>iris::base_link</parent>
        <axis>
          <xyz expressed_in='iris::__model__'>0 0 1</xyz>
          <limit>
            <lower>-1e+16</lower>
            <upper>1e+16</upper>
          </limit>
          <dynamics>
            <spring_reference>0</spring_reference>
            <spring_stiffness>0</spring_stiffness>
          </dynamics>
        </axis>
      </joint>
      <link name='iris::rotor_1'>
        <pose relative_to='iris::__model__'>-0.13 0.2 0.023 0 -0 0</pose>
        <inertial>
          <pose>0 0 0 0 -0 0</pose>
          <mass>0.005</mass>
          <inertia>
            <ixx>9.75e-07</ixx>
            <ixy>0</ixy>
            <ixz>0</ixz>
            <iyy>0.000273104</iyy>
            <iyz>0</iyz>
            <izz>0.000274004</izz>
          </inertia>
        </inertial>
        <collision name='rotor_1_collision'>
          <pose>0 0 0 0 -0 0</pose>
          <geometry>
            <cylinder>
              <length>0.005</length>
              <radius>0.128</radius>
            </cylinder>
          </geometry>
          <surface>
            <contact>
              <ode/>
            </contact>
            <friction>
              <ode/>
              <torsional>
                <ode/>
              </torsional>
            </friction>
            <bounce/>
          </surface>
          <max_contacts>10</max_contacts>
        </collision>
        <visual name='rotor_1_visual'>
          <pose>0 0 0 0 -0 0</pose>
          <geometry>
            <mesh>
              <scale>1 1 1</scale>
              <uri>model://iris/meshes/iris_prop_ccw.dae</uri>
            </mesh>
          </geometry>
          <material>
            <script>
              <name>Gazebo/DarkGrey</name>
              <uri>file://media/materials/scripts/gazebo.material</uri>
            </script>
          </material>
        </visual>
        <gravity>1</gravity>
        <velocity_decay/>
        <self_collide>0</self_collide>
        <enable_wind>0</enable_wind>
        <kinematic>0</kinematic>
      </link>
      <joint name='iris::rotor_1_joint' type='revolute'>
        <child>iris::rotor_1</child>
        <parent>iris::base_link</parent>
        <axis>
          <xyz expressed_in='iris::__model__'>0 0 1</xyz>
          <limit>
            <lower>-1e+16</lower>
            <upper>1e+16</upper>
          </limit>
          <dynamics>
            <spring_reference>0</spring_reference>
            <spring_stiffness>0</spring_stiffness>
          </dynamics>
        </axis>
      </joint>
      <link name='iris::rotor_2'>
        <pose relative_to='iris::__model__'>0.13 0.22 0.023 0 -0 0</pose>
        <inertial>
          <pose>0 0 0 0 -0 0</pose>
          <mass>0.005</mass>
          <inertia>
            <ixx>9.75e-07</ixx>
            <ixy>0</ixy>
            <ixz>0</ixz>
            <iyy>0.000273104</iyy>
            <iyz>0</iyz>
            <izz>0.000274004</izz>
          </inertia>
        </inertial>
        <collision name='rotor_2_collision'>
          <pose>0 0 0 0 -0 0</pose>
          <geometry>
            <cylinder>
              <length>0.005</length>
              <radius>0.128</radius>
            </cylinder>
          </geometry>
          <surface>
            <contact>
              <ode/>
            </contact>
            <friction>
              <ode/>
              <torsional>
                <ode/>
              </torsional>
            </friction>
            <bounce/>
          </surface>
          <max_contacts>10</max_contacts>
        </collision>
        <visual name='rotor_2_visual'>
          <pose>0 0 0 0 -0 0</pose>
          <geometry>
            <mesh>
              <scale>1 1 1</scale>
              <uri>model://iris/meshes/iris_prop_cw.dae</uri>
            </mesh>
          </geometry>
          <material>
            <script>
              <name>Gazebo/Blue</name>
              <uri>file://media/materials/scripts/gazebo.material</uri>
            </script>
          </material>
        </visual>
        <gravity>1</gravity>
        <velocity_decay/>
        <self_collide>0</self_collide>
        <enable_wind>0</enable_wind>
        <kinematic>0</kinematic>
      </link>
      <joint name='iris::rotor_2_joint' type='revolute'>
        <child>iris::rotor_2</child>
        <parent>iris::base_link</parent>
        <axis>
          <xyz expressed_in='iris::__model__'>0 0 1</xyz>
          <limit>
            <lower>-1e+16</lower>
            <upper>1e+16</upper>
          </limit>
          <dynamics>
            <spring_reference>0</spring_reference>
            <spring_stiffness>0</spring_stiffness>
          </dynamics>
        </axis>
      </joint>
      <link name='iris::rotor_3'>
        <pose relative_to='iris::__model__'>-0.13 -0.2 0.023 0 -0 0</pose>
        <inertial>
          <pose>0 0 0 0 -0 0</pose>
          <mass>0.005</mass>
          <inertia>
            <ixx>9.75e-07</ixx>
            <ixy>0</ixy>
            <ixz>0</ixz>
            <iyy>0.000273104</iyy>
            <iyz>0</iyz>
            <izz>0.000274004</izz>
          </inertia>
        </inertial>
        <collision name='rotor_3_collision'>
          <pose>0 0 0 0 -0 0</pose>
          <geometry>
            <cylinder>
              <length>0.005</length>
              <radius>0.128</radius>
            </cylinder>
          </geometry>
          <surface>
            <contact>
              <ode/>
            </contact>
            <friction>
              <ode/>
              <torsional>
                <ode/>
              </torsional>
            </friction>
            <bounce/>
          </surface>
          <max_contacts>10</max_contacts>
        </collision>
        <visual name='rotor_3_visual'>
          <pose>0 0 0 0 -0 0</pose>
          <geometry>
            <mesh>
              <scale>1 1 1</scale>
              <uri>model://iris/meshes/iris_prop_cw.dae</uri>
            </mesh>
          </geometry>
          <material>
            <script>
              <name>Gazebo/DarkGrey</name>
              <uri>file://media/materials/scripts/gazebo.material</uri>
            </script>
          </material>
        </visual>
        <gravity>1</gravity>
        <velocity_decay/>
        <self_collide>0</self_collide>
        <enable_wind>0</enable_wind>
        <kinematic>0</kinematic>
      </link>
      <joint name='iris::rotor_3_joint' type='revolute'>
        <child>iris::rotor_3</child>
        <parent>iris::base_link</parent>
        <axis>
          <xyz expressed_in='iris::__model__'>0 0 1</xyz>
          <limit>
            <lower>-1e+16</lower>
            <upper>1e+16</upper>
          </limit>
          <dynamics>
            <spring_reference>0</spring_reference>
            <spring_stiffness>0</spring_stiffness>
          </dynamics>
        </axis>
      </joint>
      <plugin name='rosbag' filename='libgazebo_multirotor_base_plugin.so'>
        <robotNamespace/>
        <linkName>iris::base_link</linkName>
        <rotorVelocitySlowdownSim>10</rotorVelocitySlowdownSim>
      </plugin>
      <plugin name='front_right_motor_model' filename='libgazebo_motor_model.so'>
        <robotNamespace/>
        <jointName>iris::rotor_0_joint</jointName>
        <linkName>iris::rotor_0</linkName>
        <turningDirection>ccw</turningDirection>
        <timeConstantUp>0.0125</timeConstantUp>
        <timeConstantDown>0.025</timeConstantDown>
        <maxRotVelocity>1100</maxRotVelocity>
        <motorConstant>5.84e-06</motorConstant>
        <momentConstant>0.06</momentConstant>
        <commandSubTopic>/gazebo/command/motor_speed</commandSubTopic>
        <motorNumber>0</motorNumber>
        <rotorDragCoefficient>0.000175</rotorDragCoefficient>
        <rollingMomentCoefficient>1e-06</rollingMomentCoefficient>
        <motorSpeedPubTopic>/motor_speed/0</motorSpeedPubTopic>
        <rotorVelocitySlowdownSim>10</rotorVelocitySlowdownSim>
      </plugin>
      <plugin name='back_left_motor_model' filename='libgazebo_motor_model.so'>
        <robotNamespace/>
        <jointName>iris::rotor_1_joint</jointName>
        <linkName>iris::rotor_1</linkName>
        <turningDirection>ccw</turningDirection>
        <timeConstantUp>0.0125</timeConstantUp>
        <timeConstantDown>0.025</timeConstantDown>
        <maxRotVelocity>1100</maxRotVelocity>
        <motorConstant>5.84e-06</motorConstant>
        <momentConstant>0.06</momentConstant>
        <commandSubTopic>/gazebo/command/motor_speed</commandSubTopic>
        <motorNumber>1</motorNumber>
        <rotorDragCoefficient>0.000175</rotorDragCoefficient>
        <rollingMomentCoefficient>1e-06</rollingMomentCoefficient>
        <motorSpeedPubTopic>/motor_speed/1</motorSpeedPubTopic>
        <rotorVelocitySlowdownSim>10</rotorVelocitySlowdownSim>
      </plugin>
      <plugin name='front_left_motor_model' filename='libgazebo_motor_model.so'>
        <robotNamespace/>
        <jointName>iris::rotor_2_joint</jointName>
        <linkName>iris::rotor_2</linkName>
        <turningDirection>cw</turningDirection>
        <timeConstantUp>0.0125</timeConstantUp>
        <timeConstantDown>0.025</timeConstantDown>
        <maxRotVelocity>1100</maxRotVelocity>
        <motorConstant>5.84e-06</motorConstant>
        <momentConstant>0.06</momentConstant>
        <commandSubTopic>/gazebo/command/motor_speed</commandSubTopic>
        <motorNumber>2</motorNumber>
        <rotorDragCoefficient>0.000175</rotorDragCoefficient>
        <rollingMomentCoefficient>1e-06</rollingMomentCoefficient>
        <motorSpeedPubTopic>/motor_speed/2</motorSpeedPubTopic>
        <rotorVelocitySlowdownSim>10</rotorVelocitySlowdownSim>
      </plugin>
      <plugin name='back_right_motor_model' filename='libgazebo_motor_model.so'>
        <robotNamespace/>
        <jointName>iris::rotor_3_joint</jointName>
        <linkName>iris::rotor_3</linkName>
        <turningDirection>cw</turningDirection>
        <timeConstantUp>0.0125</timeConstantUp>
        <timeConstantDown>0.025</timeConstantDown>
        <maxRotVelocity>1100</maxRotVelocity>
        <motorConstant>5.84e-06</motorConstant>
        <momentConstant>0.06</momentConstant>
        <commandSubTopic>/gazebo/command/motor_speed</commandSubTopic>
        <motorNumber>3</motorNumber>
        <rotorDragCoefficient>0.000175</rotorDragCoefficient>
        <rollingMomentCoefficient>1e-06</rollingMomentCoefficient>
        <motorSpeedPubTopic>/motor_speed/3</motorSpeedPubTopic>
        <rotorVelocitySlowdownSim>10</rotorVelocitySlowdownSim>
      </plugin>
      <frame name='iris::gps0::__model__' attached_to='iris::gps0::link'>
        <pose relative_to='iris::__model__'>0.05 0 0.04 0 -0 0</pose>
      </frame>
      <link name='iris::gps0::link'>
        <pose relative_to='iris::gps0::__model__'>0 0 0 0 -0 0</pose>
        <inertial>
          <pose>0 0 0 0 -0 0</pose>
          <mass>0.015</mass>
          <inertia>
            <ixx>1e-05</ixx>
            <ixy>0</ixy>
            <ixz>0</ixz>
            <iyy>1e-05</iyy>
            <iyz>0</iyz>
            <izz>1e-05</izz>
          </inertia>
        </inertial>
        <visual name='visual'>
          <geometry>
            <cylinder>
              <radius>0.01</radius>
              <length>0.002</length>
            </cylinder>
          </geometry>
          <material>
            <script>
              <name>Gazebo/Black</name>
              <uri>__default__</uri>
            </script>
          </material>
        </visual>
        <sensor name='gps' type='gps'>
          <pose>0 0 0 0 -0 0</pose>
          <update_rate>5</update_rate>
          <always_on>1</always_on>
          <visualize>0</visualize>
          <plugin name='gps_plugin' filename='libgazebo_gps_plugin.so'>
            <robotNamespace/>
            <gpsNoise>1</gpsNoise>
            <gpsXYRandomWalk>2.0</gpsXYRandomWalk>
            <gpsZRandomWalk>4.0</gpsZRandomWalk>
            <gpsXYNoiseDensity>2.0e-4</gpsXYNoiseDensity>
            <gpsZNoiseDensity>4.0e-4</gpsZNoiseDensity>
            <gpsVXYNoiseDensity>0.2</gpsVXYNoiseDensity>
            <gpsVZNoiseDensity>0.4</gpsVZNoiseDensity>
          </plugin>
          <gps/>
        </sensor>
        <self_collide>0</self_collide>
        <enable_wind>0</enable_wind>
        <kinematic>0</kinematic>
      </link>
      <joint name='iris::gps0_joint' type='fixed'>
        <child>iris::gps0::link</child>
        <parent>iris::base_link</parent>
      </joint>
      <plugin name='groundtruth_plugin' filename='libgazebo_groundtruth_plugin.so'>
        <robotNamespace/>
      </plugin>
      <plugin name='magnetometer_plugin' filename='libgazebo_magnetometer_plugin.so'>
        <robotNamespace/>
        <pubRate>100</pubRate>
        <noiseDensity>0.0004</noiseDensity>
        <randomWalk>6.4e-06</randomWalk>
        <biasCorrelationTime>600</biasCorrelationTime>
        <magTopic>/mag</magTopic>
      </plugin>
      <plugin name='barometer_plugin' filename='libgazebo_barometer_plugin.so'>
        <robotNamespace/>
        <pubRate>50</pubRate>
        <baroTopic>/baro</baroTopic>
        <baroDriftPaPerSec>0</baroDriftPaPerSec>
      </plugin>
      <plugin name='mavlink_interface' filename='libgazebo_mavlink_interface.so'>
        <robotNamespace/>
        <imuSubTopic>/imu</imuSubTopic>
        <magSubTopic>/mag</magSubTopic>
        <baroSubTopic>/baro</baroSubTopic>
        <mavlink_addr>INADDR_ANY</mavlink_addr>
        <mavlink_tcp_port>4560</mavlink_tcp_port>
        <mavlink_udp_port>14560</mavlink_udp_port>
        <serialEnabled>0</serialEnabled>
        <serialDevice>/dev/ttyACM0</serialDevice>
        <baudRate>921600</baudRate>
        <qgc_addr>INADDR_ANY</qgc_addr>
        <qgc_udp_port>14550</qgc_udp_port>
        <sdk_addr>INADDR_ANY</sdk_addr>
        <sdk_udp_port>14540</sdk_udp_port>
        <hil_mode>0</hil_mode>
        <hil_state_level>0</hil_state_level>
        <send_vision_estimation>0</send_vision_estimation>
        <send_odometry>1</send_odometry>
        <enable_lockstep>1</enable_lockstep>
        <use_tcp>1</use_tcp>
        <motorSpeedCommandPubTopic>/gazebo/command/motor_speed</motorSpeedCommandPubTopic>
        <control_channels>
          <channel name='rotor1'>
            <input_index>0</input_index>
            <input_offset>0</input_offset>
            <input_scaling>1000</input_scaling>
            <zero_position_disarmed>0</zero_position_disarmed>
            <zero_position_armed>100</zero_position_armed>
            <joint_control_type>velocity</joint_control_type>
          </channel>
          <channel name='rotor2'>
            <input_index>1</input_index>
            <input_offset>0</input_offset>
            <input_scaling>1000</input_scaling>
            <zero_position_disarmed>0</zero_position_disarmed>
            <zero_position_armed>100</zero_position_armed>
            <joint_control_type>velocity</joint_control_type>
          </channel>
          <channel name='rotor3'>
            <input_index>2</input_index>
            <input_offset>0</input_offset>
            <input_scaling>1000</input_scaling>
            <zero_position_disarmed>0</zero_position_disarmed>
            <zero_position_armed>100</zero_position_armed>
            <joint_control_type>velocity</joint_control_type>
          </channel>
          <channel name='rotor4'>
            <input_index>3</input_index>
            <input_offset>0</input_offset>
            <input_scaling>1000</input_scaling>
            <zero_position_disarmed>0</zero_position_disarmed>
            <zero_position_armed>100</zero_position_armed>
            <joint_control_type>velocity</joint_control_type>
          </channel>
          <channel name='rotor5'>
            <input_index>4</input_index>
            <input_offset>1</input_offset>
            <input_scaling>324.6</input_scaling>
            <zero_position_disarmed>0</zero_position_disarmed>
            <zero_position_armed>0</zero_position_armed>
            <joint_control_type>velocity</joint_control_type>
            <joint_control_pid>
              <p>0.1</p>
              <i>0</i>
              <d>0</d>
              <iMax>0.0</iMax>
              <iMin>0.0</iMin>
              <cmdMax>2</cmdMax>
              <cmdMin>-2</cmdMin>
            </joint_control_pid>
            <joint_name>zephyr_delta_wing::propeller_joint</joint_name>
          </channel>
          <channel name='rotor6'>
            <input_index>5</input_index>
            <input_offset>0</input_offset>
            <input_scaling>0.524</input_scaling>
            <zero_position_disarmed>0</zero_position_disarmed>
            <zero_position_armed>0</zero_position_armed>
            <joint_control_type>position</joint_control_type>
            <joint_name>zephyr_delta_wing::flap_left_joint</joint_name>
            <joint_control_pid>
              <p>10.0</p>
              <i>0</i>
              <d>0</d>
              <iMax>0</iMax>
              <iMin>0</iMin>
              <cmdMax>20</cmdMax>
              <cmdMin>-20</cmdMin>
            </joint_control_pid>
          </channel>
          <channel name='rotor7'>
            <input_index>6</input_index>
            <input_offset>0</input_offset>
            <input_scaling>0.524</input_scaling>
            <zero_position_disarmed>0</zero_position_disarmed>
            <zero_position_armed>0</zero_position_armed>
            <joint_control_type>position</joint_control_type>
            <joint_name>zephyr_delta_wing::flap_right_joint</joint_name>
            <joint_control_pid>
              <p>10.0</p>
              <i>0</i>
              <d>0</d>
              <iMax>0</iMax>
              <iMin>0</iMin>
              <cmdMax>20</cmdMax>
              <cmdMin>-20</cmdMin>
            </joint_control_pid>
          </channel>
          <channel name='rotor8'>
            <input_index>7</input_index>
            <input_offset>0</input_offset>
            <input_scaling>0.524</input_scaling>
            <zero_position_disarmed>0</zero_position_disarmed>
            <zero_position_armed>0</zero_position_armed>
            <joint_control_type>position</joint_control_type>
          </channel>
        </control_channels>
      </plugin>
      <static>0</static>
      <plugin name='rotors_gazebo_imu_plugin' filename='libgazebo_imu_plugin.so'>
        <robotNamespace/>
        <linkName>iris::/imu_link</linkName>
        <imuTopic>/imu</imuTopic>
      </plugin>
      <link name='stereo_camera_link'>
        <pose>0.1 0 0 0 -0 0</pose>
        <inertial>
          <mass>0.01</mass>
          <inertia>
            <ixx>4.15e-06</ixx>
            <ixy>0</ixy>
            <ixz>0</ixz>
            <iyy>2.407e-06</iyy>
            <iyz>0</iyz>
            <izz>2.407e-06</izz>
          </inertia>
          <pose>0 0 0 0 -0 0</pose>
        </inertial>
        <sensor name='stereo_camera' type='multicamera'>
          <update_rate>20</update_rate>
          <camera name='left'>
            <pose>0 0.05 0 0 -0 0</pose>
            <horizontal_fov>1.39626</horizontal_fov>
            <image>
              <width>640</width>
              <height>480</height>
              <format>R8G8B8</format>
            </image>
            <clip>
              <near>0.02</near>
              <far>300</far>
            </clip>
            <noise>
              <type>gaussian</type>
              <mean>0</mean>
              <stddev>0.007</stddev>
            </noise>
          </camera>
          <camera name='right'>
            <pose>0 -0.05 0 0 -0 0</pose>
            <horizontal_fov>1.39626</horizontal_fov>
            <image>
              <width>640</width>
              <height>480</height>
              <format>R8G8B8</format>
            </image>
            <clip>
              <near>0.02</near>
              <far>300</far>
            </clip>
            <noise>
              <type>gaussian</type>
              <mean>0</mean>
              <stddev>0.007</stddev>
            </noise>
          </camera>
          <plugin name='stereo_camera_controller' filename='libgazebo_ros_multicamera.so'>
            <alwaysOn>1</alwaysOn>
            <updateRate>20.0</updateRate>
            <cameraName>stereo_ir</cameraName>
            <imageTopicName>image_raw</imageTopicName>
            <cameraInfoTopicName>camera_info</cameraInfoTopicName>
            <frameName>stereo_camera_link</frameName>
            <hackBaseline>0.1</hackBaseline>
            <distortionK1>0.0</distortionK1>
            <distortionK2>0.0</distortionK2>
            <distortionK3>0.0</distortionK3>
            <distortionT1>0.0</distortionT1>
            <distortionT2>0.0</distortionT2>
            <robotNamespace>/</robotNamespace>
          </plugin>
        </sensor>
        <self_collide>0</self_collide>
        <enable_wind>0</enable_wind>
        <kinematic>0</kinematic>
      </link>
      <joint name='stereo_camera_joint' type='fixed'>
        <child>stereo_camera_link</child>
        <parent>iris::base_link</parent>
        <pose>0.1 0 0 0 -0 0</pose>
      </joint>
      <link name='realsense_rgbd_link'>
        <pose>0.1 0 0 0 -0 0</pose>
        <inertial>
          <mass>0.01</mass>
          <inertia>
            <ixx>4.15e-06</ixx>
            <ixy>0</ixy>
            <ixz>0</ixz>
            <iyy>2.407e-06</iyy>
            <iyz>0</iyz>
            <izz>2.407e-06</izz>
          </inertia>
          <pose>0 0 0 0 -0 0</pose>
        </inertial>
        <sensor name='realsense_rgbd' type='depth'>
          <update_rate>15</update_rate>
          <camera>
            <horizontal_fov>1.50098</horizontal_fov>
            <image>
              <width>640</width>
              <height>480</height>
              <format>R8G8B8</format>
            </image>
            <clip>
              <near>0.05</near>
              <far>20</far>
            </clip>
          </camera>
          <plugin name='realsense_rgbd_controller' filename='libgazebo_ros_openni_kinect.so'>
            <alwaysOn>1</alwaysOn>
            <updateRate>15.0</updateRate>
            <cameraName>camera</cameraName>
            <imageTopicName>color/image_raw</imageTopicName>
            <cameraInfoTopicName>color/camera_info</cameraInfoTopicName>
            <depthImageTopicName>aligned_depth_to_color/image_raw</depthImageTopicName>
            <depthImageCameraInfoTopicName>aligned_depth_to_color/camera_info</depthImageCameraInfoTopicName>
            <pointCloudTopicName>depth/color/points</pointCloudTopicName>
            <frameName>camera_color_optical_frame</frameName>
            <pointCloudCutoff>0.2</pointCloudCutoff>
            <pointCloudCutoffMax>10.0</pointCloudCutoffMax>
            <distortion_k1>0.0</distortion_k1>
            <distortion_k2>0.0</distortion_k2>
            <distortion_k3>0.0</distortion_k3>
            <distortion_t1>0.0</distortion_t1>
            <distortion_t2>0.0</distortion_t2>
            <robotNamespace>/</robotNamespace>
          </plugin>
        </sensor>
        <self_collide>0</self_collide>
        <enable_wind>0</enable_wind>
        <kinematic>0</kinematic>
      </link>
      <joint name='realsense_rgbd_joint' type='fixed'>
        <child>realsense_rgbd_link</child>
        <parent>iris::base_link</parent>
        <pose>0.1 0 0 0 -0 0</pose>
      </joint>
      <plugin name='imu_plugin' filename='libgazebo_ros_imu.so'>
        <alwaysOn>1</alwaysOn>
        <bodyName>iris::base_link</bodyName>
        <topicName>/imu/data</topicName>
        <serviceName>imu_service</serviceName>
        <gaussianNoise>0.01</gaussianNoise>
        <updateRate>200.0</updateRate>
        <imu>
          <noise>
            <type>gaussian</type>
            <rate>
              <mean>0.0</mean>
              <stddev>0.001</stddev>
              <bias_mean>0.0</bias_mean>
              <bias_stddev>0.0002</bias_stddev>
            </rate>
            <accel>
              <mean>0.0</mean>
              <stddev>0.01</stddev>
              <bias_mean>0.0</bias_mean>
              <bias_stddev>0.0002</bias_stddev>
            </accel>
          </noise>
        </imu>
        <robotNamespace>/</robotNamespace>
      </plugin>
      <plugin name='gps_plugin' filename='libhector_gazebo_ros_gps.so'>
        <updateRate>10.0</updateRate>
        <bodyName>iris::base_link</bodyName>
        <frameId>base_link</frameId>
        <topicName>/gps/fix</topicName>
        <velocityTopicName>/gps/fix_velocity</velocityTopicName>
        <referenceLatitude>22.332</referenceLatitude>
        <referenceLongitude>114.265</referenceLongitude>
        <referenceAltitude>10.0</referenceAltitude>
        <referenceHeading>0</referenceHeading>
        <drift>0.0001 0.0001 0.0001</drift>
        <gaussianNoise>0.01 0.01 0.01</gaussianNoise>
        <velocityDrift>0 0 0</velocityDrift>
        <velocityGaussianNoise>0.01 0.01 0.01</velocityGaussianNoise>
        <robotNamespace>/</robotNamespace>
      </plugin>
      <plugin name='world_wind_plugin' filename='/home/ncu/catkin_ws/devel/lib/libworld_wind_plugin.so'>
        <link_name>iris::base_link</link_name>
        <robotNamespace>/</robotNamespace>
      </plugin>
      <plugin name='body_force_plugin' filename='/home/ncu/catkin_ws/devel/lib/libbody_force_plugin.so'>
        <link_name>iris::base_link</link_name>
        <robotNamespace>/</robotNamespace>
      </plugin>
      <pose>0 0 0 0 -0 0</pose>
    </model>
    <light name='user_point_light_0' type='point'>
      <pose>4.05694 -7.3372 1 0 -0 0</pose>
      <diffuse>0.5 0.5 0.5 1</diffuse>
      <specular>0.1 0.1 0.1 1</specular>
      <attenuation>
        <range>20</range>
        <constant>0.5</constant>
        <linear>0.01</linear>
        <quadratic>0.001</quadratic>
      </attenuation>
      <cast_shadows>0</cast_shadows>
      <direction>0 0 -1</direction>
      <spot>
        <inner_angle>0</inner_angle>
        <outer_angle>0</outer_angle>
        <falloff>0</falloff>
      </spot>
    </light>
    <light name='user_point_light_1' type='point'>
      <pose>4.15686 9.34267 1 0 -0 0</pose>
      <diffuse>0.5 0.5 0.5 1</diffuse>
      <specular>0.1 0.1 0.1 1</specular>
      <attenuation>
        <range>20</range>
        <constant>0.5</constant>
        <linear>0.01</linear>
        <quadratic>0.001</quadratic>
      </attenuation>
      <cast_shadows>0</cast_shadows>
      <direction>0 0 -1</direction>
      <spot>
        <inner_angle>0</inner_angle>
        <outer_angle>0</outer_angle>
        <falloff>0</falloff>
      </spot>
    </light>
    <light name='user_point_light_2' type='point'>
      <pose>18.1297 -14.4554 1 0 -0 0</pose>
      <diffuse>0.5 0.5 0.5 1</diffuse>
      <specular>0.1 0.1 0.1 1</specular>
      <attenuation>
        <range>20</range>
        <constant>0.5</constant>
        <linear>0.01</linear>
        <quadratic>0.001</quadratic>
      </attenuation>
      <cast_shadows>0</cast_shadows>
      <direction>0 0 -1</direction>
      <spot>
        <inner_angle>0</inner_angle>
        <outer_angle>0</outer_angle>
        <falloff>0</falloff>
      </spot>
    </light>
    <light name='user_point_light_3' type='point'>
      <pose>13.4781 -25.0767 1 0 -0 0</pose>
      <diffuse>0.5 0.5 0.5 1</diffuse>
      <specular>0.1 0.1 0.1 1</specular>
      <attenuation>
        <range>20</range>
        <constant>0.5</constant>
        <linear>0.01</linear>
        <quadratic>0.001</quadratic>
      </attenuation>
      <cast_shadows>0</cast_shadows>
      <direction>0 0 -1</direction>
      <spot>
        <inner_angle>0</inner_angle>
        <outer_angle>0</outer_angle>
        <falloff>0</falloff>
      </spot>
    </light>
    <state world_name='default'>
      <sim_time>174 23000000</sim_time>
      <real_time>60 991546517</real_time>
      <wall_time>1778588158 481831611</wall_time>
      <iterations>59574</iterations>
      <model name='ground_plane'>
        <pose>0 0 0 0 -0 0</pose>
        <scale>1 1 1</scale>
        <link name='link'>
          <pose>0 0 0 0 -0 0</pose>
          <velocity>0 0 0 0 -0 0</velocity>
          <acceleration>0 0 0 0 -0 0</acceleration>
          <wrench>0 0 0 0 -0 0</wrench>
        </link>
      </model>
      <model name='iris'>
        <pose>1e-06 -0 0.054016 0 1.9e-05 0</pose>
        <scale>1 1 1</scale>
        <link name='iris::/imu_link'>
          <pose>2e-06 -0 0.074016 0 1.9e-05 0</pose>
          <velocity>0 -0 0 2e-06 -0 0</velocity>
          <acceleration>-0 -1.6e-05 0 0.004231 -0 -3e-06</acceleration>
          <wrench>-0 -0 0 0 -0 0</wrench>
        </link>
        <link name='iris::base_link'>
          <pose>1e-06 -0 0.054016 0 1.9e-05 0</pose>
          <velocity>0 -0 0 0 -0 0</velocity>
          <acceleration>-0 -8e-06 0 0.000151 -0 0</acceleration>
          <wrench>-0 -1.2e-05 0 0 -0 0</wrench>
        </link>
        <link name='iris::gps0::link'>
          <pose>0.050002 -0 0.094015 0 1.9e-05 0</pose>
          <velocity>0 -0 0 0 -0 0</velocity>
          <acceleration>-0 -2.3e-05 0 0.000132 -0 1.8e-05</acceleration>
          <wrench>-0 -0 0 0 -0 0</wrench>
        </link>
        <link name='iris::rotor_0'>
          <pose>0.130002 -0.22 0.077014 0 1.9e-05 0</pose>
          <velocity>0 -0 0 0 -0 0</velocity>
          <acceleration>-0 -1.4e-05 -3.3e-05 0.00015 -0 0</acceleration>
          <wrench>-0 -0 -0 0 -0 0</wrench>
        </link>
        <link name='iris::rotor_1'>
          <pose>-0.129998 0.2 0.077019 0 1.9e-05 0</pose>
          <velocity>0 -0 0 0 -0 0</velocity>
          <acceleration>0 -1.4e-05 3e-05 0.00015 -0 0</acceleration>
          <wrench>0 -0 0 0 -0 0</wrench>
        </link>
        <link name='iris::rotor_2'>
          <pose>0.130002 0.22 0.077014 0 1.9e-05 0</pose>
          <velocity>0 -0 0 0 -0 0</velocity>
          <acceleration>0 -1.4e-05 3.3e-05 0.00015 -0 0</acceleration>
          <wrench>0 -0 0 0 -0 0</wrench>
        </link>
        <link name='iris::rotor_3'>
          <pose>-0.129998 -0.2 0.077019 0 1.9e-05 0</pose>
          <velocity>0 -0 0 0 -0 0</velocity>
          <acceleration>-0 -1.4e-05 -3e-05 0.00015 -0 0</acceleration>
          <wrench>-0 -0 -0 0 -0 0</wrench>
        </link>
        <link name='realsense_rgbd_link'>
          <pose>0.100001 -0 0.054011 0 5e-06 0</pose>
          <velocity>0 -1e-06 0 0 -0 6e-06</velocity>
          <acceleration>-0 -0.00288 -0 0.000149 -0 0.012476</acceleration>
          <wrench>-0 -2.9e-05 -0 0 -0 0</wrench>
        </link>
        <link name='stereo_camera_link'>
          <pose>0.100001 -0 0.054011 0 5e-06 0</pose>
          <velocity>0 -1e-06 0 0 -0 6e-06</velocity>
          <acceleration>-0 -0.00288 -0 0.000149 0 0.012472</acceleration>
          <wrench>-0 -2.9e-05 -0 0 -0 0</wrench>
        </link>
      </model>
      <light name='sun'>
        <pose>0 0 10 0 -0 0</pose>
      </light>
      <light name='user_point_light_0'>
        <pose>4.05694 -7.3372 1 0 -0 0</pose>
      </light>
      <light name='user_point_light_1'>
        <pose>4.15686 9.34267 1 0 -0 0</pose>
      </light>
      <light name='user_point_light_2'>
        <pose>18.1297 -14.4554 1 0 -0 0</pose>
      </light>
      <light name='user_point_light_3'>
        <pose>13.4781 -25.0767 41.7967 0 -0 0</pose>
      </light>
    </state>
    <gui fullscreen='0'>
      <camera name='user_camera'>
        <pose>-81.7716 40.9566 111.898 0 0.891643 -0.61581</pose>
        <view_controller>orbit</view_controller>
        <projection_type>perspective</projection_type>
      </camera>
    </gui>
  </world>
</sdf>
